<?xml version="0.0" ?>
<robot name="bolt.urdf">
  <link name="base">
    <inertial>
      <origin rpy="0 0 0" xyz="0 0 0"/>
      <mass value="0.01"/>
      <inertia ixx="-4.46E-06" ixy="-4.55E-07" ixz="1.95E-06" iyy="-2.47E-06" iyz="8.51E-08" izz="2.17E-06"/>
    </inertial>
    <visual>
      <origin rpy="0 0 0" xyz="0 0 0"/>
      <geometry>
        <box size=".046 .046 0.08"/>
      </geometry>
      <material name="blue">
      </material>
    </visual>
    <collision>
      <origin rpy="0 0 0" xyz="0 0 0"/>
      <geometry>
        <box size=".046 .046 0.08"/>
      </geometry>
    </collision>
  </link>
  <joint name="joint1" type="revolute">
    <origin rpy="0 0 0" xyz="0 0 0.03"/>
    <parent link="base"/>
    <child link="top"/>
    <axis xyz="0 0 1"/>
    <limit effort="10" lower="-3.1415" upper="3.1415" velocity="2.1750"/>
  </joint>
  <link name="top">
    <inertial>
      <origin rpy="0 0 0" xyz="0 0 0"/>
      <mass value="0.01"/>
      <inertia ixx="-4.46E-06" ixy="-4.55E-07" ixz="1.95E-06" iyy="-2.47E-06" iyz="8.51E-08" izz="2.17E-06"/>
    </inertial>
    <visual>
      <origin rpy="0 0 0" xyz="0 0 0"/>
      <geometry>
        <box size=".026 .026 0.05"/>
      </geometry>
      <material name="blue">
      </material>
    </visual>
    <collision>
      <origin rpy="0 0 0" xyz="0 0 0"/>
      <geometry>
        <box size=".026 .026 0.05"/>
      </geometry>
    </collision>
  </link>

  <material name="panda_white">
    <color rgba="1. 1. 1. 1."/>
  </material>
  <material name="red">
    <color rgba="1.0 0. 0. 1.0"/>
  </material>
  <material name="blue">
    <color rgba="0. 0. 1. 1.0"/>
  </material>
  <material name="green">
    <color rgba="0. 1. 0. 1.0"/>
  </material>

</robot>


