<?xml version="1.0" ?>
<robot name="partnet_c75ebd7c340649ba5ad304c2564ae1df">
	
	
	<link name="base">
		<inertial>
			<origin rpy="0 0 0" xyz="0 0 0"/>
			<mass value="0.0"/>
			<inertia ixx="0.9" ixy="0.9" ixz="0.9" iyy="0.9" iyz="0.9" izz="0.9"/>
		</inertial>
	</link>
	
	
	<link name="link_0">
		
		
		<visual name="door_frame-9">
			
			
			<origin rpy="0.0 0.0 0.0" xyz="0.6994047812620767 -0.3716736367086352 -0.4594064542801477"/>
			
			
			<geometry>
				
				
				<mesh filename="textured_objs/original-2.obj"/>
				
			
			</geometry>
			
		
		</visual>
		
		
		<visual name="glass-10">
			
			
			<origin rpy="0.0 0.0 0.0" xyz="0.6994047812620767 -0.3716736367086352 -0.4594064542801477"/>
			
			
			<geometry>
				
				
				<mesh filename="textured_objs/original-6.obj"/>
				
			
			</geometry>
			
		
		</visual>
		
		
		<visual name="glass-10">
			
			
			<origin rpy="0.0 0.0 0.0" xyz="0.6994047812620767 -0.3716736367086352 -0.4594064542801477"/>
			
			
			<geometry>
				
				
				<mesh filename="textured_objs/original-9.obj"/>
				
			
			</geometry>
			
		
		</visual>
		
		
		<visual name="glass-10">
			
			
			<origin rpy="0.0 0.0 0.0" xyz="0.6994047812620767 -0.3716736367086352 -0.4594064542801477"/>
			
			
			<geometry>
				
				
				<mesh filename="textured_objs/original-8.obj"/>
				
			
			</geometry>
			
		
		</visual>
		
		
		<visual name="glass-10">
			
			
			<origin rpy="0.0 0.0 0.0" xyz="0.6994047812620767 -0.3716736367086352 -0.4594064542801477"/>
			
			
			<geometry>
				
				
				<mesh filename="textured_objs/original-15.obj"/>
				
			
			</geometry>
			
		
		</visual>
		
		
		<visual name="glass-10">
			
			
			<origin rpy="0.0 0.0 0.0" xyz="0.6994047812620767 -0.3716736367086352 -0.4594064542801477"/>
			
			
			<geometry>
				
				
				<mesh filename="textured_objs/original-10.obj"/>
				
			
			</geometry>
			
		
		</visual>
		
		
		<visual name="glass-10">
			
			
			<origin rpy="0.0 0.0 0.0" xyz="0.6994047812620767 -0.3716736367086352 -0.4594064542801477"/>
			
			
			<geometry>
				
				
				<mesh filename="textured_objs/original-12.obj"/>
				
			
			</geometry>
			
		
		</visual>
		
		
		<visual name="glass-10">
			
			
			<origin rpy="0.0 0.0 0.0" xyz="0.6994047812620767 -0.3716736367086352 -0.4594064542801477"/>
			
			
			<geometry>
				
				
				<mesh filename="textured_objs/original-14.obj"/>
				
			
			</geometry>
			
		
		</visual>
		
		
		<visual name="glass-10">
			
			
			<origin rpy="0.0 0.0 0.0" xyz="0.6994047812620767 -0.3716736367086352 -0.4594064542801477"/>
			
			
			<geometry>
				
				
				<mesh filename="textured_objs/original-11.obj"/>
				
			
			</geometry>
			
		
		</visual>
		
		
		<visual name="glass-10">
			
			
			<origin rpy="0.0 0.0 0.0" xyz="0.6994047812620767 -0.3716736367086352 -0.4594064542801477"/>
			
			
			<geometry>
				
				
				<mesh filename="textured_objs/original-13.obj"/>
				
			
			</geometry>
			
		
		</visual>
		
		
		<visual name="glass-10">
			
			
			<origin rpy="0.0 0.0 0.0" xyz="0.6994047812620767 -0.3716736367086352 -0.4594064542801477"/>
			
			
			<geometry>
				
				
				<mesh filename="textured_objs/original-5.obj"/>
				
			
			</geometry>
			
		
		</visual>
		
		
		<visual name="glass-10">
			
			
			<origin rpy="0.0 0.0 0.0" xyz="0.6994047812620767 -0.3716736367086352 -0.4594064542801477"/>
			
			
			<geometry>
				
				
				<mesh filename="textured_objs/original-16.obj"/>
				
			
			</geometry>
			
		
		</visual>
		
		
		<collision>
			
			
			<origin rpy="0.0 0.0 0.0" xyz="0.6994047812620767 -0.3716736367086352 -0.4594064542801477"/>
			
			
			<geometry>
				
				
				<mesh filename="textured_objs/original-2.obj"/>
				
			
			</geometry>
			
		
		</collision>
		
		
		<collision>
			
			
			<origin rpy="0.0 0.0 0.0" xyz="0.6994047812620767 -0.3716736367086352 -0.4594064542801477"/>
			
			
			<geometry>
				
				
				<mesh filename="textured_objs/original-6.obj"/>
				
			
			</geometry>
			
		
		</collision>
		
		
		<collision>
			
			
			<origin rpy="0.0 0.0 0.0" xyz="0.6994047812620767 -0.3716736367086352 -0.4594064542801477"/>
			
			
			<geometry>
				
				
				<mesh filename="textured_objs/original-9.obj"/>
				
			
			</geometry>
			
		
		</collision>
		
		
		<collision>
			
			
			<origin rpy="0.0 0.0 0.0" xyz="0.6994047812620767 -0.3716736367086352 -0.4594064542801477"/>
			
			
			<geometry>
				
				
				<mesh filename="textured_objs/original-8.obj"/>
				
			
			</geometry>
			
		
		</collision>
		
		
		<collision>
			
			
			<origin rpy="0.0 0.0 0.0" xyz="0.6994047812620767 -0.3716736367086352 -0.4594064542801477"/>
			
			
			<geometry>
				
				
				<mesh filename="textured_objs/original-15.obj"/>
				
			
			</geometry>
			
		
		</collision>
		
		
		<collision>
			
			
			<origin rpy="0.0 0.0 0.0" xyz="0.6994047812620767 -0.3716736367086352 -0.4594064542801477"/>
			
			
			<geometry>
				
				
				<mesh filename="textured_objs/original-10.obj"/>
				
			
			</geometry>
			
		
		</collision>
		
		
		<collision>
			
			
			<origin rpy="0.0 0.0 0.0" xyz="0.6994047812620767 -0.3716736367086352 -0.4594064542801477"/>
			
			
			<geometry>
				
				
				<mesh filename="textured_objs/original-12.obj"/>
				
			
			</geometry>
			
		
		</collision>
		
		
		<collision>
			
			
			<origin rpy="0.0 0.0 0.0" xyz="0.6994047812620767 -0.3716736367086352 -0.4594064542801477"/>
			
			
			<geometry>
				
				
				<mesh filename="textured_objs/original-14.obj"/>
				
			
			</geometry>
			
		
		</collision>
		
		
		<collision>
			
			
			<origin rpy="0.0 0.0 0.0" xyz="0.6994047812620767 -0.3716736367086352 -0.4594064542801477"/>
			
			
			<geometry>
				
				
				<mesh filename="textured_objs/original-11.obj"/>
				
			
			</geometry>
			
		
		</collision>
		
		
		<collision>
			
			
			<origin rpy="0.0 0.0 0.0" xyz="0.6994047812620767 -0.3716736367086352 -0.4594064542801477"/>
			
			
			<geometry>
				
				
				<mesh filename="textured_objs/original-13.obj"/>
				
			
			</geometry>
			
		
		</collision>
		
		
		<collision>
			
			
			<origin rpy="0.0 0.0 0.0" xyz="0.6994047812620767 -0.3716736367086352 -0.4594064542801477"/>
			
			
			<geometry>
				
				
				<mesh filename="textured_objs/original-5.obj"/>
				
			
			</geometry>
			
		
		</collision>
		
		
		<collision>
			
			
			<origin rpy="0.0 0.0 0.0" xyz="0.6994047812620767 -0.3716736367086352 -0.4594064542801477"/>
			
			
			<geometry>
				
				
				<mesh filename="textured_objs/original-16.obj"/>
				
			
			</geometry>
			
		
		</collision>
		
	
		<inertial>
			<origin rpy="0 0 0" xyz="0 0 0"/>
			<mass value="3.0"/>
			<inertia ixx="0.9" ixy="0.9" ixz="0.9" iyy="0.9" iyz="0.9" izz="0.9"/>
		</inertial>
	</link>
	
	
	<joint name="joint_0" type="revolute">
		
		
		<origin rpy="0.0 0.0 0.0" xyz="-0.6994047812620767 0.3716736367086352 0.4594064542801477"/>
		
		
		<axis xyz="0 -1 0"/>
		
		
		<child link="link_0"/>
		
		
		<parent link="link_5"/>
		
		
		<limit lower="-0.0" upper="1.5707963267948966"/>
		
	
	</joint>
	
	
	<link name="link_1">
		
		
		<visual name="door_button-5">
			
			
			<origin rpy="0.0 0.0 0.0" xyz="0 0 0"/>
			
			
			<geometry>
				
				
				<mesh filename="textured_objs/original-22.obj"/>
				
			
			</geometry>
			
		
		</visual>
		
		
		<collision>
			
			
			<origin rpy="0.0 0.0 0.0" xyz="0 0 0"/>
			
			
			<geometry>
				
				
				<mesh filename="textured_objs/original-22.obj"/>
				
			
			</geometry>
			
		
		</collision>
		
	
		<inertial>
			<origin rpy="0 0 0" xyz="0 0 0"/>
			<mass value="3.0"/>
			<inertia ixx="0.9" ixy="0.9" ixz="0.9" iyy="0.9" iyz="0.9" izz="0.9"/>
		</inertial>
	</link>
	
	
	<joint name="joint_1" type="prismatic">
		
		
		<origin rpy="0.0 0.0 0.0" xyz="0 0 0"/>
		
		
		<axis xyz="0 0 -1"/>
		
		
		<child link="link_1"/>
		
		
		<parent link="link_5"/>
		
		
		<limit lower="0.0040000000000000036" upper="0.01200000000000001"/>
		
	
	</joint>
	
	
	<link name="link_2">
		
		
		<visual name="control_button-6">
			
			
			<origin rpy="0.0 0.0 0.0" xyz="-0.595905953683902 0.10762880873845218 0"/>
			
			
			<geometry>
				
				
				<mesh filename="textured_objs/original-21.obj"/>
				
			
			</geometry>
			
		
		</visual>
		
		
		<collision>
			
			
			<origin rpy="0.0 0.0 0.0" xyz="-0.595905953683902 0.10762880873845218 0"/>
			
			
			<geometry>
				
				
				<mesh filename="textured_objs/original-21.obj"/>
				
			
			</geometry>
			
		
		</collision>
		
	
		<inertial>
			<origin rpy="0 0 0" xyz="0 0 0"/>
			<mass value="3.0"/>
			<inertia ixx="0.9" ixy="0.9" ixz="0.9" iyy="0.9" iyz="0.9" izz="0.9"/>
		</inertial>
	</link>
	
	
	<joint name="joint_2" type="continuous">
		
		
		<origin rpy="0.0 0.0 0.0" xyz="0.595905953683902 -0.10762880873845218 0"/>
		
		
		<axis xyz="0 0 1"/>
		
		
		<child link="link_2"/>
		
		
		<parent link="link_5"/>
		
	
	</joint>
	
	
	<link name="link_3">
		
		
		<visual name="control_button-7">
			
			
			<origin rpy="0.0 0.0 0.0" xyz="-0.5959056708108185 -0.10520150832160682 0"/>
			
			
			<geometry>
				
				
				<mesh filename="textured_objs/original-20.obj"/>
				
			
			</geometry>
			
		
		</visual>
		
		
		<collision>
			
			
			<origin rpy="0.0 0.0 0.0" xyz="-0.5959056708108185 -0.10520150832160682 0"/>
			
			
			<geometry>
				
				
				<mesh filename="textured_objs/original-20.obj"/>
				
			
			</geometry>
			
		
		</collision>
		
	
		<inertial>
			<origin rpy="0 0 0" xyz="0 0 0"/>
			<mass value="3.0"/>
			<inertia ixx="0.9" ixy="0.9" ixz="0.9" iyy="0.9" iyz="0.9" izz="0.9"/>
		</inertial>
	</link>
	
	
	<joint name="joint_3" type="continuous">
		
		
		<origin rpy="0.0 0.0 0.0" xyz="0.5959056708108185 0.10520150832160682 0"/>
		
		
		<axis xyz="0 0 1"/>
		
		
		<child link="link_3"/>
		
		
		<parent link="link_5"/>
		
	
	</joint>
	
	
	<link name="link_4">
		
		
		<visual name="tray-12">
			
			
			<origin rpy="0.0 0.0 0.0" xyz="0.149241880774498 0 0.02379955083131792"/>
			
			
			<geometry>
				
				
				<mesh filename="textured_objs/original-44.obj"/>
				
			
			</geometry>
			
		
		</visual>
		
		
		<visual name="tray_support-13">
			
			
			<origin rpy="0.0 0.0 0.0" xyz="0.149241880774498 0 0.02379955083131792"/>
			
			
			<geometry>
				
				
				<mesh filename="textured_objs/original-43.obj"/>
				
			
			</geometry>
			
		
		</visual>
		
		
		<visual name="tray_support-13">
			
			
			<origin rpy="0.0 0.0 0.0" xyz="0.149241880774498 0 0.02379955083131792"/>
			
			
			<geometry>
				
				
				<mesh filename="textured_objs/original-45.obj"/>
				
			
			</geometry>
			
		
		</visual>
		
		
		<visual name="tray_support-13">
			
			
			<origin rpy="0.0 0.0 0.0" xyz="0.149241880774498 0 0.02379955083131792"/>
			
			
			<geometry>
				
				
				<mesh filename="textured_objs/original-41.obj"/>
				
			
			</geometry>
			
		
		</visual>
		
		
		<visual name="tray_support-13">
			
			
			<origin rpy="0.0 0.0 0.0" xyz="0.149241880774498 0 0.02379955083131792"/>
			
			
			<geometry>
				
				
				<mesh filename="textured_objs/original-42.obj"/>
				
			
			</geometry>
			
		
		</visual>
		
		
		<collision>
			
			
			<origin rpy="0.0 0.0 0.0" xyz="0.149241880774498 0 0.02379955083131792"/>
			
			
			<geometry>
				
				
				<mesh filename="textured_objs/original-44.obj"/>
				
			
			</geometry>
			
		
		</collision>
		
		
		<collision>
			
			
			<origin rpy="0.0 0.0 0.0" xyz="0.149241880774498 0 0.02379955083131792"/>
			
			
			<geometry>
				
				
				<mesh filename="textured_objs/original-43.obj"/>
				
			
			</geometry>
			
		
		</collision>
		
		
		<collision>
			
			
			<origin rpy="0.0 0.0 0.0" xyz="0.149241880774498 0 0.02379955083131792"/>
			
			
			<geometry>
				
				
				<mesh filename="textured_objs/original-45.obj"/>
				
			
			</geometry>
			
		
		</collision>
		
		
		<collision>
			
			
			<origin rpy="0.0 0.0 0.0" xyz="0.149241880774498 0 0.02379955083131792"/>
			
			
			<geometry>
				
				
				<mesh filename="textured_objs/original-41.obj"/>
				
			
			</geometry>
			
		
		</collision>
		
		
		<collision>
			
			
			<origin rpy="0.0 0.0 0.0" xyz="0.149241880774498 0 0.02379955083131792"/>
			
			
			<geometry>
				
				
				<mesh filename="textured_objs/original-42.obj"/>
				
			
			</geometry>
			
		
		</collision>
		
	
		<inertial>
			<origin rpy="0 0 0" xyz="0 0 0"/>
			<mass value="3.0"/>
			<inertia ixx="0.9" ixy="0.9" ixz="0.9" iyy="0.9" iyz="0.9" izz="0.9"/>
		</inertial>
	</link>
	
	
	<joint name="joint_4" type="continuous">
		
		
		<origin rpy="0.0 0.0 0.0" xyz="-0.149241880774498 0 -0.02379955083131792"/>
		
		
		<axis xyz="0 1 0"/>
		
		
		<child link="link_4"/>
		
		
		<parent link="link_5"/>
		
	
	</joint>
	
	
	<link name="link_5">
		
		
		<visual name="frame-2">
			
			
			<origin rpy="0.0 0.0 0.0" xyz="0 0 0"/>
			
			
			<geometry>
				
				
				<mesh filename="textured_objs/original-36.obj"/>
				
			
			</geometry>
			
		
		</visual>
		
		
		<visual name="display_panel-8">
			
			
			<origin rpy="0.0 0.0 0.0" xyz="0 0 0"/>
			
			
			<geometry>
				
				
				<mesh filename="textured_objs/original-26.obj"/>
				
			
			</geometry>
			
		
		</visual>
		
		
		<visual name="display_panel-8">
			
			
			<origin rpy="0.0 0.0 0.0" xyz="0 0 0"/>
			
			
			<geometry>
				
				
				<mesh filename="textured_objs/original-27.obj"/>
				
			
			</geometry>
			
		
		</visual>
		
		
		<visual name="display_panel-8">
			
			
			<origin rpy="0.0 0.0 0.0" xyz="0 0 0"/>
			
			
			<geometry>
				
				
				<mesh filename="textured_objs/original-28.obj"/>
				
			
			</geometry>
			
		
		</visual>
		
		
		<visual name="display_panel-8">
			
			
			<origin rpy="0.0 0.0 0.0" xyz="0 0 0"/>
			
			
			<geometry>
				
				
				<mesh filename="textured_objs/original-29.obj"/>
				
			
			</geometry>
			
		
		</visual>
		
		
		<visual name="display_panel-8">
			
			
			<origin rpy="0.0 0.0 0.0" xyz="0 0 0"/>
			
			
			<geometry>
				
				
				<mesh filename="textured_objs/original-30.obj"/>
				
			
			</geometry>
			
		
		</visual>
		
		
		<visual name="display_panel-8">
			
			
			<origin rpy="0.0 0.0 0.0" xyz="0 0 0"/>
			
			
			<geometry>
				
				
				<mesh filename="textured_objs/original-31.obj"/>
				
			
			</geometry>
			
		
		</visual>
		
		
		<visual name="display_panel-8">
			
			
			<origin rpy="0.0 0.0 0.0" xyz="0 0 0"/>
			
			
			<geometry>
				
				
				<mesh filename="textured_objs/original-34.obj"/>
				
			
			</geometry>
			
		
		</visual>
		
		
		<visual name="display_panel-8">
			
			
			<origin rpy="0.0 0.0 0.0" xyz="0 0 0"/>
			
			
			<geometry>
				
				
				<mesh filename="textured_objs/original-33.obj"/>
				
			
			</geometry>
			
		
		</visual>
		
		
		<visual name="display_panel-8">
			
			
			<origin rpy="0.0 0.0 0.0" xyz="0 0 0"/>
			
			
			<geometry>
				
				
				<mesh filename="textured_objs/original-32.obj"/>
				
			
			</geometry>
			
		
		</visual>
		
		
		<visual name="display_panel-8">
			
			
			<origin rpy="0.0 0.0 0.0" xyz="0 0 0"/>
			
			
			<geometry>
				
				
				<mesh filename="textured_objs/original-35.obj"/>
				
			
			</geometry>
			
		
		</visual>
		
		
		<visual name="display_panel-8">
			
			
			<origin rpy="0.0 0.0 0.0" xyz="0 0 0"/>
			
			
			<geometry>
				
				
				<mesh filename="textured_objs/original-23.obj"/>
				
			
			</geometry>
			
		
		</visual>
		
		
		<collision>
			
			
			<origin rpy="0.0 0.0 0.0" xyz="0 0 0"/>
			
			
			<geometry>
				
				
				<mesh filename="textured_objs/original-36.obj"/>
				
			
			</geometry>
			
		
		</collision>
		
		
		<collision>
			
			
			<origin rpy="0.0 0.0 0.0" xyz="0 0 0"/>
			
			
			<geometry>
				
				
				<mesh filename="textured_objs/original-26.obj"/>
				
			
			</geometry>
			
		
		</collision>
		
		
		<collision>
			
			
			<origin rpy="0.0 0.0 0.0" xyz="0 0 0"/>
			
			
			<geometry>
				
				
				<mesh filename="textured_objs/original-27.obj"/>
				
			
			</geometry>
			
		
		</collision>
		
		
		<collision>
			
			
			<origin rpy="0.0 0.0 0.0" xyz="0 0 0"/>
			
			
			<geometry>
				
				
				<mesh filename="textured_objs/original-28.obj"/>
				
			
			</geometry>
			
		
		</collision>
		
		
		<collision>
			
			
			<origin rpy="0.0 0.0 0.0" xyz="0 0 0"/>
			
			
			<geometry>
				
				
				<mesh filename="textured_objs/original-29.obj"/>
				
			
			</geometry>
			
		
		</collision>
		
		
		<collision>
			
			
			<origin rpy="0.0 0.0 0.0" xyz="0 0 0"/>
			
			
			<geometry>
				
				
				<mesh filename="textured_objs/original-30.obj"/>
				
			
			</geometry>
			
		
		</collision>
		
		
		<collision>
			
			
			<origin rpy="0.0 0.0 0.0" xyz="0 0 0"/>
			
			
			<geometry>
				
				
				<mesh filename="textured_objs/original-31.obj"/>
				
			
			</geometry>
			
		
		</collision>
		
		
		<collision>
			
			
			<origin rpy="0.0 0.0 0.0" xyz="0 0 0"/>
			
			
			<geometry>
				
				
				<mesh filename="textured_objs/original-34.obj"/>
				
			
			</geometry>
			
		
		</collision>
		
		
		<collision>
			
			
			<origin rpy="0.0 0.0 0.0" xyz="0 0 0"/>
			
			
			<geometry>
				
				
				<mesh filename="textured_objs/original-33.obj"/>
				
			
			</geometry>
			
		
		</collision>
		
		
		<collision>
			
			
			<origin rpy="0.0 0.0 0.0" xyz="0 0 0"/>
			
			
			<geometry>
				
				
				<mesh filename="textured_objs/original-32.obj"/>
				
			
			</geometry>
			
		
		</collision>
		
		
		<collision>
			
			
			<origin rpy="0.0 0.0 0.0" xyz="0 0 0"/>
			
			
			<geometry>
				
				
				<mesh filename="textured_objs/original-35.obj"/>
				
			
			</geometry>
			
		
		</collision>
		
		
		<collision>
			
			
			<origin rpy="0.0 0.0 0.0" xyz="0 0 0"/>
			
			
			<geometry>
				
				
				<mesh filename="textured_objs/original-23.obj"/>
				
			
			</geometry>
			
		
		</collision>
		
	
		<inertial>
			<origin rpy="0 0 0" xyz="0 0 0"/>
			<mass value="3.0"/>
			<inertia ixx="0.9" ixy="0.9" ixz="0.9" iyy="0.9" iyz="0.9" izz="0.9"/>
		</inertial>
	</link>
	
	
	<joint name="joint_5" type="fixed">
		
		
		<origin rpy="1.570796326794897 0 -1.570796326794897" xyz="0 0 0"/>
		
		
		<child link="link_5"/>
		
		
		<parent link="base"/>
		
	
	</joint>
	

</robot>
