<?xml version="1.0" ?>
<robot name="partnet_c75ebd7c340649ba5ad304c2564ae1df">
	
	
	<link name="base">
		<inertial>
			<origin rpy="0 0 0" xyz="0 0 0"/>
			<mass value="0.0"/>
			<inertia ixx="0.9" ixy="0.9" ixz="0.9" iyy="0.9" iyz="0.9" izz="0.9"/>
		</inertial>
	</link>
	
	
	<link name="link_0">
		
		
		<inertial>
			<origin rpy="0 0 0" xyz="0 0 0"/>
			<mass value="3.0"/>
			<inertia ixx="0.9" ixy="0.9" ixz="0.9" iyy="0.9" iyz="0.9" izz="0.9"/>
		</inertial>
	</link>
	
	
	<joint name="joint_0" type="revolute">
		
		
		<origin rpy="0.0 0.0 0.0" xyz="-0.6994047812620767 0.3716736367086352 0.4594064542801477"/>
		
		
		<axis xyz="0 -1 0"/>
		
		
		<child link="link_0"/>
		
		
		<parent link="link_5"/>
		
		
		<limit lower="-0.0" upper="1.5707963267948966"/>
		
	
	</joint>
	
	
	<link name="link_1">
		
		
		<visual name="door_button-5">
			
			
			<origin rpy="0.0 0.0 0.0" xyz="0 0 0"/>
			
			
			<geometry>
				
				
				<mesh filename="textured_objs/original-22.obj"/>
				
			
			</geometry>
			
		
		</visual>
		
		
		<inertial>
			<origin rpy="0 0 0" xyz="0 0 0"/>
			<mass value="3.0"/>
			<inertia ixx="0.9" ixy="0.9" ixz="0.9" iyy="0.9" iyz="0.9" izz="0.9"/>
		</inertial>
	</link>
	
	
	<joint name="joint_1" type="prismatic">
		
		
		<origin rpy="0.0 0.0 0.0" xyz="0 0 0"/>
		
		
		<axis xyz="0 0 -1"/>
		
		
		<child link="link_1"/>
		
		
		<parent link="link_5"/>
		
		
		<limit lower="0.0040000000000000036" upper="0.01200000000000001"/>
		
	
	</joint>
	
	
	<link name="link_2">
		
		
		<inertial>
			<origin rpy="0 0 0" xyz="0 0 0"/>
			<mass value="3.0"/>
			<inertia ixx="0.9" ixy="0.9" ixz="0.9" iyy="0.9" iyz="0.9" izz="0.9"/>
		</inertial>
	</link>
	
	
	<joint name="joint_2" type="continuous">
		
		
		<origin rpy="0.0 0.0 0.0" xyz="0.595905953683902 -0.10762880873845218 0"/>
		
		
		<axis xyz="0 0 1"/>
		
		
		<child link="link_2"/>
		
		
		<parent link="link_5"/>
		
	
	</joint>
	
	
	<link name="link_3">
		
		
		<inertial>
			<origin rpy="0 0 0" xyz="0 0 0"/>
			<mass value="3.0"/>
			<inertia ixx="0.9" ixy="0.9" ixz="0.9" iyy="0.9" iyz="0.9" izz="0.9"/>
		</inertial>
	</link>
	
	
	<joint name="joint_3" type="continuous">
		
		
		<origin rpy="0.0 0.0 0.0" xyz="0.5959056708108185 0.10520150832160682 0"/>
		
		
		<axis xyz="0 0 1"/>
		
		
		<child link="link_3"/>
		
		
		<parent link="link_5"/>
		
	
	</joint>
	
	
	<link name="link_4">
		
		
		<inertial>
			<origin rpy="0 0 0" xyz="0 0 0"/>
			<mass value="3.0"/>
			<inertia ixx="0.9" ixy="0.9" ixz="0.9" iyy="0.9" iyz="0.9" izz="0.9"/>
		</inertial>
	</link>
	
	
	<joint name="joint_4" type="continuous">
		
		
		<origin rpy="0.0 0.0 0.0" xyz="-0.149241880774498 0 -0.02379955083131792"/>
		
		
		<axis xyz="0 1 0"/>
		
		
		<child link="link_4"/>
		
		
		<parent link="link_5"/>
		
	
	</joint>
	
	
	<link name="link_5">
		
		
		<inertial>
			<origin rpy="0 0 0" xyz="0 0 0"/>
			<mass value="3.0"/>
			<inertia ixx="0.9" ixy="0.9" ixz="0.9" iyy="0.9" iyz="0.9" izz="0.9"/>
		</inertial>
	</link>
	
	
	<joint name="joint_5" type="fixed">
		
		
		<origin rpy="1.570796326794897 0 -1.570796326794897" xyz="0 0 0"/>
		
		
		<child link="link_5"/>
		
		
		<parent link="base"/>
		
	
	</joint>
	

</robot>
